<?xml version="1.0" encoding="utf-8"?>
<!-- This URDF was automatically created by SolidWorks to URDF Exporter! Originally created by Stephen Brawner (brawner@gmail.com) 
     Commit Version: 1.5.1-0-g916b5db  Build Version: 1.5.7152.31018
     For more information, please see http://wiki.ros.org/sw_urdf_exporter -->
<robot
  name="oro_new">
  <link
    name="base_link">
    <inertial>
      <origin
        xyz="-0.0475847148739974 0.0357095679967018 0.0200560337059205"
        rpy="0 0 0" />
      <mass
        value="1.32433618055244" />
      <inertia
        ixx="0.00108529406787132"
        ixy="-0.000355533730225369"
        ixz="8.17114522823693E-07"
        iyy="0.000887793616740204"
        iyz="9.92571293802781E-07"
        izz="0.00194080718355059" />
    </inertial>
    <visual>
      <origin
        xyz="0 0 0"
        rpy="0 0 0" />
      <geometry>
        <mesh
          filename="package://oro_new/meshes/base_link.STL" />
      </geometry>
      <material
        name="">
        <color
          rgba="0.752941176470588 0.752941176470588 0.752941176470588 1" />
      </material>
    </visual>
    <collision>
      <origin
        xyz="0 0 0"
        rpy="0 0 0" />
      <geometry>
        <mesh
          filename="package://oro_new/meshes/base_link.STL" />
      </geometry>
    </collision>
  </link>
  <link
    name="wheel_left">
    <inertial>
      <origin
        xyz="-0.251310190290994 -0.205425342030346 0.349949612105679"
        rpy="0 0 0" />
      <mass
        value="2.93317977791768" />
      <inertia
        ixx="0.578211586150878"
        ixy="-0.00060371823615542"
        ixz="0.0854824441641389"
        iyy="0.590904672553994"
        iyz="-0.000426721759157614"
        izz="0.0306958836148462" />
    </inertial>
    <visual>
      <origin
        xyz="0 0 0"
        rpy="0 0 0" />
      <geometry>
        <mesh
          filename="package://oro_new/meshes/wheel_left.STL" />
      </geometry>
      <material
        name="">
        <color
          rgba="0.298039215686275 0.298039215686275 0.298039215686275 1" />
      </material>
    </visual>
    <collision>
      <origin
        xyz="0 0 0"
        rpy="0 0 0" />
      <geometry>
        <mesh
          filename="package://oro_new/meshes/wheel_left.STL" />
      </geometry>
    </collision>
  </link>
  <joint
    name="wheel_left_joint"
    type="continuous">
    <origin
      xyz="-0.242519526797119 -0.170162162680993 -0.018480323531233"
      rpy="0 0.149555140664513 3.13449781269223" />
    <parent
      link="base_link" />
    <child
      link="wheel_left" />
    <axis
      xyz="0 1 0" />
  </joint>
  <link
    name="wheel_right">
    <inertial>
      <origin
        xyz="0.342218437086374 -0.0643684667502143 0.261740489942176"
        rpy="0 0 0" />
      <mass
        value="2.93317977791768" />
      <inertia
        ixx="0.484337019358045"
        ixy="-0.000453529248021569"
        ixz="-0.223366544848544"
        iyy="0.590904672553994"
        iyz="0.00058384791649383"
        izz="0.124570450407679" />
    </inertial>
    <visual>
      <origin
        xyz="0 0 0"
        rpy="0 0 0" />
      <geometry>
        <mesh
          filename="package://oro_new/meshes/wheel_right.STL" />
      </geometry>
      <material
        name="">
        <color
          rgba="0.298039215686275 0.298039215686275 0.298039215686275 1" />
      </material>
    </visual>
    <collision>
      <origin
        xyz="0 0 0"
        rpy="0 0 0" />
      <geometry>
        <mesh
          filename="package://oro_new/meshes/wheel_right.STL" />
      </geometry>
    </collision>
  </link>
  <joint
    name="wheel_right_joint"
    type="continuous">
    <origin
      xyz="-0.24061 0.099625 -0.01848"
      rpy="0 -0.44463 -0.0070948" />
    <parent
      link="base_link" />
    <child
      link="wheel_right" />
    <axis
      xyz="0 1 0" />
  </joint>
  <link
    name="base_scan">
    <inertial>
      <origin
        xyz="0.326999446048758 0.0186211756030543 -0.0113153908792468"
        rpy="0 0 0" />
      <mass
        value="0.0530538307331328" />
      <inertia
        ixx="2.44802060835082E-05"
        ixy="-3.98365719799404E-06"
        ixz="-8.44148861034125E-06"
        iyy="4.4601058988135E-05"
        iyz="-3.00606260010057E-06"
        izz="2.93834408723212E-05" />
    </inertial>
    <visual>
      <origin
        xyz="0 0 0"
        rpy="0 0 0" />
      <geometry>
        <mesh
          filename="package://oro_new/meshes/base_scan.STL" />
      </geometry>
      <material
        name="">
        <color
          rgba="0.792156862745098 0.819607843137255 0.933333333333333 1" />
      </material>
    </visual>
    <collision>
      <origin
        xyz="0 0 0"
        rpy="0 0 0" />
      <geometry>
        <mesh
          filename="package://oro_new/meshes/base_scan.STL" />
      </geometry>
    </collision>
  </link>
  <joint
    name="base_scan_joint"
    type="fixed">
    <origin
      xyz="-0.293 -0.034904 0.06947"
      rpy="1.5708 0 -0.0070948" />
    <parent
      link="base_link" />
    <child
      link="base_scan" />
    <axis
      xyz="0 0 0" />
  </joint>
  <link
    name="neck">
    <inertial>
      <origin
        xyz="0.0587444813614796 0.262222078594368 -0.459295528120781"
        rpy="0 0 0" />
      <mass
        value="1.10926755879378" />
      <inertia
        ixx="0.056445797646221"
        ixy="2.70130921791241E-05"
        ixz="-1.46486179703237E-07"
        iyy="0.0564616651066496"
        iyz="1.09599149902765E-07"
        izz="0.000391068857931652" />
    </inertial>
    <visual>
      <origin
        xyz="0 0 0"
        rpy="0 0 0" />
      <geometry>
        <mesh
          filename="package://oro_new/meshes/neck.STL" />
      </geometry>
      <material
        name="">
        <color
          rgba="0.752941176470588 0.752941176470588 0.752941176470588 1" />
      </material>
    </visual>
    <collision>
      <origin
        xyz="0 0 0"
        rpy="0 0 0" />
      <geometry>
        <mesh
          filename="package://oro_new/meshes/neck.STL" />
      </geometry>
    </collision>
  </link>
  <joint
    name="neck_joint"
    type="fixed">
    <origin
      xyz="-0.111522868965688 -0.223111765630108 0.978912848528942"
      rpy="0 0 -0.00709484089756157" />
    <parent
      link="base_link" />
    <child
      link="neck" />
    <axis
      xyz="0 0 0" />
  </joint>
  <link
    name="pan">
    <inertial>
      <origin
        xyz="0.148814365841074 0.0688778874333684 0.0481501799146573"
        rpy="0 0 0" />
      <mass
        value="0.0446711336598691" />
      <inertia
        ixx="1.17132663342199E-05"
        ixy="-9.56493405367382E-07"
        ixz="1.06434285440329E-07"
        iyy="1.111988224285E-05"
        iyz="1.4857794566596E-07"
        izz="7.78082427281012E-06" />
    </inertial>
    <visual>
      <origin
        xyz="0 0 0"
        rpy="0 0 0" />
      <geometry>
        <mesh
          filename="package://oro_new/meshes/pan.STL" />
      </geometry>
      <material
        name="">
        <color
          rgba="0.752941176470588 0.752941176470588 0.752941176470588 1" />
      </material>
    </visual>
    <collision>
      <origin
        xyz="0 0 0"
        rpy="0 0 0" />
      <geometry>
        <mesh
          filename="package://oro_new/meshes/pan.STL" />
      </geometry>
    </collision>
  </link>
  <joint
    name="pan_joint"
    type="continuous">
    <origin
      xyz="-0.0803690267279755 0.186890382040786 0.0492568279398251"
      rpy="0 0 -0.00757105682660417" />
    <parent
      link="neck" />
    <child
      link="pan" />
    <axis
      xyz="0 0 1" />
  </joint>
  <link
    name="tilt">
    <inertial>
      <origin
        xyz="-0.0613908848053771 -0.16218416914339 -0.102381542144555"
        rpy="0 0 0" />
      <mass
        value="0.190333563757372" />
      <inertia
        ixx="0.000291058829149478"
        ixy="-0.000143569690123905"
        ixz="2.0765847898897E-06"
        iyy="0.000376918038505799"
        iyz="-1.06012065218424E-06"
        izz="0.000309930369297491" />
    </inertial>
    <visual>
      <origin
        xyz="0 0 0"
        rpy="0 0 0" />
      <geometry>
        <mesh
          filename="package://oro_new/meshes/tilt.STL" />
      </geometry>
      <material
        name="">
        <color
          rgba="0.894117647058823 0.913725490196078 0.929411764705882 1" />
      </material>
    </visual>
    <collision>
      <origin
        xyz="0 0 0"
        rpy="0 0 0" />
      <geometry>
        <mesh
          filename="package://oro_new/meshes/tilt.STL" />
      </geometry>
    </collision>
  </link>
  <joint
    name="tilt_joint"
    type="continuous">
    <origin
      xyz="0.000250000000001249 0 0.0420800000000014"
      rpy="-3.12696731241166 0 -1.5707963267949" />
    <parent
      link="pan" />
    <child
      link="tilt" />
    <axis
      xyz="1 0 0" />
  </joint>
  <link
    name="depth_cam">
    <inertial>
      <origin
        xyz="-0.157044558146606 0.173807894528382 -0.150114546115025"
        rpy="0 0 0" />
      <mass
        value="0.153126622909889" />
      <inertia
        ixx="0.000147114581762331"
        ixy="-2.46612538738801E-06"
        ixz="-0.000168515913728417"
        iyy="0.000377900331187149"
        iyz="-1.84448489390364E-06"
        izz="0.000251695855150495" />
    </inertial>
    <visual>
      <origin
        xyz="0 0 0"
        rpy="0 0 0" />
      <geometry>
        <mesh
          filename="package://oro_new/meshes/depth_cam.STL" />
      </geometry>
      <material
        name="">
        <color
          rgba="0.792156862745098 0.819607843137255 0.933333333333333 1" />
      </material>
    </visual>
    <collision>
      <origin
        xyz="0 0 0"
        rpy="0 0 0" />
      <geometry>
        <mesh
          filename="package://oro_new/meshes/depth_cam.STL" />
      </geometry>
    </collision>
  </link>
  <joint
    name="depth_cam_joint"
    type="fixed">
    <origin
      xyz="0.0874623622012928 0 0"
      rpy="-1.57079632679489 0 0" />
    <parent
      link="tilt" />
    <child
      link="depth_cam" />
    <axis
      xyz="0 0 0" />
  </joint>
</robot>