<?xml version="1.0" encoding="utf-8"?>
<robot name="oro" xmlns:xacro="http://ros.org/wiki/xacro">
  <xacro:include filename="$(find oro_description)/urdf/common_properties.xacro"/>
  <!--<xacro:include filename="$(find oro_description)/urdf/oro_waffle.gazebo.xacro"/>-->

  <xacro:property name="r200_cam_rgb_px" value="0.005"/>
  <xacro:property name="r200_cam_rgb_py" value="0.018"/>
  <xacro:property name="r200_cam_rgb_pz" value="0.013"/>
  <xacro:property name="r200_cam_depth_offset" value="0.01"/>

  <link name="base_footprint"/>

  <joint name="base_joint" type="fixed">
    <parent link="base_footprint"/>
    <child link="base_link" />
    <origin xyz="0 0 0.010" rpy="0 0 0"/>
  </joint>

  <link name="base_link">
    <visual>
      <origin xyz="-0.064 0 0.0" rpy="0 0 0"/>
      <geometry>
	<mesh filename="package://oro_description/meshes/bases/waffle_base.stl" scale="0.001 0.001 0.001"/>
	<!--<mesh filename="package://oro_description/meshes/base_link.STL" />-->
      </geometry>
      <material name="blue"/>
    </visual>

    <collision>
      <origin xyz="-0.064 0 0.047" rpy="0 0 0"/>
      <geometry>
        <box size="0.266 0.266 0.094"/>
      </geometry>
    </collision>
    
    <inertial>
      <origin xyz="0 0 0" rpy="0 0 0"/>
      <mass value="1.3729096e+00"/>
      <inertia ixx="8.7002718e-03" ixy="-4.7576583e-05" ixz="1.1160499e-04"
               iyy="8.6195418e-03" iyz="-3.5422299e-06"
               izz="1.4612727e-02" />
    </inertial>
  </link>

  <joint name="wheel_left_joint" type="continuous">
    <parent link="base_link"/>
    <child link="wheel_left_link"/>
    <origin xyz="0.0 0.144 0.023" rpy="-1.57 0 0"/>
    <axis xyz="0 0 1"/>
  </joint>

  <link name="wheel_left_link">
    <visual>
      <origin xyz="0 0 0" rpy="1.57 0 0"/>
      <geometry>
        <mesh filename="package://oro_description/meshes/wheels/left_tire.stl" scale="0.001 0.001 0.001"/>
      </geometry>
      <material name="dark"/>
    </visual>

    <collision>
      <origin xyz="0 0 0" rpy="0 0 0"/>
      <geometry>
        <cylinder length="0.018" radius="0.033"/>
      </geometry>
    </collision>

    <inertial>
      <origin xyz="0 0 0" />
      <mass value="2.8498940e-02" />
      <inertia ixx="1.1175580e-05" ixy="-4.2369783e-11" ixz="-5.9381719e-09"
               iyy="1.1192413e-05" iyz="-1.4400107e-11"
               izz="2.0712558e-05" />
      </inertial>
  </link>

  <joint name="wheel_right_joint" type="continuous">
    <parent link="base_link"/>
    <child link="wheel_right_link"/>
    <origin xyz="0.0 -0.144 0.023" rpy="-1.57 0 0"/>
    <axis xyz="0 0 1"/>
  </joint>

  <link name="wheel_right_link">
    <visual>
      <origin xyz="0 0 0" rpy="1.57 0 0"/>
      <geometry>
        <mesh filename="package://oro_description/meshes/wheels/right_tire.stl" scale="0.001 0.001 0.001"/>
      </geometry>
      <material name="dark"/>
    </visual>

    <collision>
      <origin xyz="0 0 0" rpy="0 0 0"/>
      <geometry>
        <cylinder length="0.018" radius="0.033"/>
      </geometry>
    </collision>

    <inertial>
      <origin xyz="0 0 0" />
      <mass value="2.8498940e-02" />
      <inertia ixx="1.1175580e-05" ixy="-4.2369783e-11" ixz="-5.9381719e-09"
               iyy="1.1192413e-05" iyz="-1.4400107e-11"
               izz="2.0712558e-05" />
      </inertial>
  </link>

  <joint name="caster_back_right_joint" type="fixed">
    <parent link="base_link"/>
    <child link="caster_back_right_link"/>
    <origin xyz="-0.177 -0.064 -0.004" rpy="-1.57 0 0"/>
  </joint>

  <link name="caster_back_right_link">
    <collision>
      <origin xyz="0 0.001 0" rpy="0 0 0"/>
      <geometry>
        <box size="0.030 0.009 0.020"/>
      </geometry>
    </collision>

    <inertial>
      <origin xyz="0 0 0" />
      <mass value="0.005" />
      <inertia ixx="0.001" ixy="0.0" ixz="0.0"
               iyy="0.001" iyz="0.0"
               izz="0.001" />
    </inertial>
  </link>

  <joint name="caster_back_left_joint" type="fixed">
    <parent link="base_link"/>
    <child link="caster_back_left_link"/>
    <origin xyz="-0.177 0.064 -0.004" rpy="-1.57 0 0"/>
  </joint>

  <link name="caster_back_left_link">
    <collision>
      <origin xyz="0 0.001 0" rpy="0 0 0"/>
      <geometry>
        <box size="0.030 0.009 0.020"/>
      </geometry>
    </collision>

    <inertial>
      <origin xyz="0 0 0" />
      <mass value="0.005" />
      <inertia ixx="0.001" ixy="0.0" ixz="0.0"
               iyy="0.001" iyz="0.0"
               izz="0.001" />
    </inertial>
  </link>
  <link
    name="base_scan">
    <inertial>
      <origin
        xyz="0.326999446048758 0.0186211756030543 -0.0113153908792468"
        rpy="0 0 0" />
      <mass
        value="0.0530538307331328" />
      <inertia
        ixx="2.44802060835082E-05"
        ixy="-3.98365719799404E-06"
        ixz="-8.44148861034125E-06"
        iyy="4.4601058988135E-05"
        iyz="-3.00606260010057E-06"
        izz="2.93834408723212E-05" />
    </inertial>
    <visual>
      <origin
        xyz="0 0 0"
        rpy="0 0 0" />
      <geometry>
        <mesh
          filename="package://oro_description/meshes/base_scan.STL" />
      </geometry>
      <material
        name="">
        <color
          rgba="0.792156862745098 0.819607843137255 0.933333333333333 1" />
      </material>
    </visual>
    <collision>
      <origin
        xyz="0 0 0"
        rpy="0 0 0" />
      <geometry>
        <mesh
          filename="package://oro_description/meshes/base_scan.STL" />
      </geometry>
    </collision>
  </link>
  <joint
    name="base_scan_joint"
    type="fixed">
    <origin
      xyz="-0.293 -0.034904 0.06947"
      rpy="0 0 0" />
      <!--rpy="1.5708 0 -0.0070948" />-->
    <parent
      link="base_link" />
    <child
      link="base_scan" />
    <axis
      xyz="0 0 0" />
  </joint>
  <link
    name="neck">
    <inertial>
      <origin
        xyz="0.0587444813614796 0.262222078594368 -0.459295528120781"
        rpy="0 0 0" />
      <mass
        value="1.10926755879378" />
      <inertia
        ixx="0.056445797646221"
        ixy="2.70130921791241E-05"
        ixz="-1.46486179703237E-07"
        iyy="0.0564616651066496"
        iyz="1.09599149902765E-07"
        izz="0.000391068857931652" />
    </inertial>
    <visual>
      <origin
        xyz="0 0 0"
        rpy="0 0 0" />
      <geometry>
        <mesh
          filename="package://oro_description/meshes/neck.STL" />
      </geometry>
      <material
        name="">
        <color
          rgba="0.752941176470588 0.752941176470588 0.752941176470588 1" />
      </material>
    </visual>
    <collision>
      <origin
        xyz="0 0 0"
        rpy="0 0 0" />
      <geometry>
        <mesh
          filename="package://oro_description/meshes/neck.STL" />
      </geometry>
    </collision>
  </link>
  <joint
    name="neck_joint"
    type="fixed">
    <origin
      xyz="-0.111522868965688 -0.223111765630108 0.978912848528942"
      rpy="0 0 0" />
      <!--rpy="0 0 -0.00709484089756157" />-->
    <parent
      link="base_link" />
    <child
      link="neck" />
    <axis
      xyz="0 0 0" />
  </joint>
  <link
    name="pan">
    <inertial>
      <origin
        xyz="0.148814365841074 0.0688778874333684 0.0481501799146573"
        rpy="0 0 0" />
      <mass
        value="0.0446711336598691" />
      <inertia
        ixx="1.17132663342199E-05"
        ixy="-9.56493405367382E-07"
        ixz="1.06434285440329E-07"
        iyy="1.111988224285E-05"
        iyz="1.4857794566596E-07"
        izz="7.78082427281012E-06" />
    </inertial>
    <visual>
      <origin
        xyz="0 0 0"
        rpy="0 0 0" />
      <geometry>
        <mesh
          filename="package://oro_description/meshes/pan.STL" />
      </geometry>
      <material
        name="">
        <color
          rgba="0.752941176470588 0.752941176470588 0.752941176470588 1" />
      </material>
    </visual>
    <collision>
      <origin
        xyz="0 0 0"
        rpy="0 0 0" />
      <geometry>
        <mesh
          filename="package://oro_description/meshes/pan.STL" />
      </geometry>
    </collision>
  </link>
  <joint
    name="pan_joint"
    type="continuous">
    <origin
      xyz="-0.0803690267279755 0.186890382040786 0.0492568279398251"
      rpy="0 0 -0.00757105682660417" />
    <parent
      link="neck" />
    <child
      link="pan" />
    <axis
      xyz="0 0 1" />
  </joint>
  <link
    name="tilt">
    <inertial>
      <origin
        xyz="-0.0613908848053771 -0.16218416914339 -0.102381542144555"
        rpy="0 0 0" />
      <mass
        value="0.190333563757372" />
      <inertia
        ixx="0.000291058829149478"
        ixy="-0.000143569690123905"
        ixz="2.0765847898897E-06"
        iyy="0.000376918038505799"
        iyz="-1.06012065218424E-06"
        izz="0.000309930369297491" />
    </inertial>
    <visual>
      <origin
        xyz="0 0 0"
        rpy="0 0 0" />
      <geometry>
        <mesh
          filename="package://oro_description/meshes/tilt.STL" />
      </geometry>
      <material
        name="">
        <color
          rgba="0.894117647058823 0.913725490196078 0.929411764705882 1" />
      </material>
    </visual>
    <collision>
      <origin
        xyz="0 0 0"
        rpy="0 0 0" />
      <geometry>
        <mesh
          filename="package://oro_description/meshes/tilt.STL" />
      </geometry>
    </collision>
  </link>
  <joint
    name="tilt_joint"
    type="continuous">
    <origin
      xyz="0.000250000000001249 0 0.0420800000000014"
      rpy="-3.12696731241166 0 -1.5707963267949" />
    <parent
      link="pan" />
    <child
      link="tilt" />
    <axis
      xyz="1 0 0" />
  </joint>
  <link
    name="depth_cam">
    <inertial>
      <origin
        xyz="-0.157044558146606 0.173807894528382 -0.150114546115025"
        rpy="0 0 0" />
      <mass
        value="0.153126622909889" />
      <inertia
        ixx="0.000147114581762331"
        ixy="-2.46612538738801E-06"
        ixz="-0.000168515913728417"
        iyy="0.000377900331187149"
        iyz="-1.84448489390364E-06"
        izz="0.000251695855150495" />
    </inertial>
    <visual>
      <origin
        xyz="0 0 0"
        rpy="0 0 0" />
      <geometry>
        <mesh
          filename="package://oro_description/meshes/depth_cam.STL" />
      </geometry>
      <material
        name="">
        <color
          rgba="0.792156862745098 0.819607843137255 0.933333333333333 1" />
      </material>
    </visual>
    <collision>
      <origin
        xyz="0 0 0"
        rpy="0 0 0" />
      <geometry>
        <mesh
          filename="package://oro_description/meshes/depth_cam.STL" />
      </geometry>
    </collision>
  </link>
  <joint
    name="depth_cam_joint"
    type="fixed">
    <origin
      xyz="0.0874623622012928 0 0"
      rpy="-1.57079632679489 0 0" />
    <parent
      link="tilt" />
    <child
      link="depth_cam" />
    <axis
      xyz="0 0 0" />
  </joint>
</robot>
