<?xml version="1.0" encoding="utf-8"?>
<!-- This URDF was automatically created by SolidWorks to URDF Exporter! Originally created by Stephen Brawner (brawner@gmail.com) 
     Commit Version: 1.5.1-0-g916b5db  Build Version: 1.5.7152.31018
     For more information, please see http://wiki.ros.org/sw_urdf_exporter -->
<robot
  name="oro_v4">
  <link
    name="base_link">
    <inertial>
      <origin
        xyz="-0.0594924771131361 -0.000350515629269713 0.0200560323783756"
        rpy="0 0 0" />
      <mass
        value="1.32433600289921" />
      <inertia
        ixx="0.00135553657024012"
        ixy="-1.92790642264976E-07"
        ixz="5.02179862659706E-08"
        iyy="0.000617550917743685"
        iyz="1.28466065345707E-06"
        izz="0.00194080698723539" />
    </inertial>
    <visual>
      <origin
        xyz="0 0 0"
        rpy="0 0 0" />
      <geometry>
        <mesh
          filename="package://oro_v4/meshes/base_link.STL" />
      </geometry>
      <material
        name="">
        <color
          rgba="0.752941176470588 0.752941176470588 0.752941176470588 1" />
      </material>
    </visual>
    <collision>
      <origin
        xyz="0 0 0"
        rpy="0 0 0" />
      <geometry>
        <mesh
          filename="package://oro_v4/meshes/base_link.STL" />
      </geometry>
    </collision>
  </link>
  <link
    name="wheel_left">
    <inertial>
      <origin
        xyz="-0.24029688570582 -0.171403830474243 0.3516090394338"
        rpy="0 0 0" />
      <mass
        value="2.93317977791768" />
      <inertia
        ixx="0.578713938142483"
        ixy="-6.51968372103197E-05"
        ixz="0.0855514545164607"
        iyy="0.59039318262637"
        iyz="0.000346010278877057"
        izz="0.0307052749788487" />
    </inertial>
    <visual>
      <origin
        xyz="0 0 0"
        rpy="0 0 0" />
      <geometry>
        <mesh
          filename="package://oro_v4/meshes/wheel_left.STL" />
      </geometry>
      <material
        name="">
        <color
          rgba="0.298039215686275 0.298039215686275 0.298039215686275 1" />
      </material>
    </visual>
    <collision>
      <origin
        xyz="0 0 0"
        rpy="0 0 0" />
      <geometry>
        <mesh
          filename="package://oro_v4/meshes/wheel_left.STL" />
      </geometry>
    </collision>
  </link>
  <joint
    name="wheel_left_joint"
    type="continuous">
    <origin
      xyz="-0.242519526797119 -0.170162162680993 -0.018480323531233"
      rpy="0 0.149555140664513 3.13449781269223" />
    <parent
      link="base_link" />
    <child
      link="wheel_left" />
    <axis
      xyz="0 1 0" />
  </joint>
  <link
    name="wheel_right">
    <inertial>
      <origin
        xyz="0.332163711519925 -0.0983899783063174 0.26653100877906"
        rpy="0 0 0" />
      <mass
        value="2.93317977791768" />
      <inertia
        ixx="0.484759277148023"
        ixy="-0.000163003310076326"
        ixz="-0.22356104583953"
        iyy="0.59039318262637"
        iyz="-0.0003120955968529"
        izz="0.124659935973308" />
    </inertial>
    <visual>
      <origin
        xyz="0 0 0"
        rpy="0 0 0" />
      <geometry>
        <mesh
          filename="package://oro_v4/meshes/wheel_right.STL" />
      </geometry>
      <material
        name="">
        <color
          rgba="0.298039215686275 0.298039215686275 0.298039215686275 1" />
      </material>
    </visual>
    <collision>
      <origin
        xyz="0 0 0"
        rpy="0 0 0" />
      <geometry>
        <mesh
          filename="package://oro_v4/meshes/wheel_right.STL" />
      </geometry>
    </collision>
  </link>
  <joint
    name="wheel_right_joint"
    type="continuous">
    <origin
      xyz="-0.24060539870727 0.0996248558539564 -0.018480323531233"
      rpy="0 -0.444631589877229 -0.00709484089756432" />
    <parent
      link="base_link" />
    <child
      link="wheel_right" />
    <axis
      xyz="0 1 0" />
  </joint>
  <link
    name="base_scan">
    <inertial>
      <origin
        xyz="0.335546547080464 0.0186211665621306 -0.03726790390847"
        rpy="0 0 0" />
      <mass
        value="0.0530538694104073" />
      <inertia
        ixx="1.81421128914862E-05"
        ixy="-4.99056789044237E-06"
        ixz="9.84834689423623E-08"
        iyy="4.4601102506138E-05"
        iyz="1.6158313804672E-08"
        izz="3.57215832578884E-05" />
    </inertial>
    <visual>
      <origin
        xyz="0 0 0"
        rpy="0 0 0" />
      <geometry>
        <mesh
          filename="package://oro_v4/meshes/base_scan.STL" />
      </geometry>
      <material
        name="">
        <color
          rgba="0.792156862745098 0.819607843137255 0.933333333333333 1" />
      </material>
    </visual>
    <collision>
      <origin
        xyz="0 0 0"
        rpy="0 0 0" />
      <geometry>
        <mesh
          filename="package://oro_v4/meshes/base_scan.STL" />
      </geometry>
    </collision>
  </link>
  <joint
    name="base_scan_joint"
    type="fixed">
    <origin
      xyz="-0.29299616822181 -0.034903733333453 0.069469676468767"
      rpy="1.5707963267949 0 -0.00709484089756434" />
    <parent
      link="base_link" />
    <child
      link="base_scan" />
    <axis
      xyz="0 0 0" />
  </joint>
  <link
    name="neck">
    <inertial>
      <origin
        xyz="0.0459897562048886 0.22344669916928 -0.459295524453743"
        rpy="0 0 0" />
      <mass
        value="1.10926754952808" />
      <inertia
        ixx="0.0564255801556195"
        ixy="-4.00387537666084E-07"
        ixz="-1.8294698739588E-07"
        iyy="0.0564818825679269"
        iyz="-1.33980954038881E-09"
        izz="0.000391068830002546" />
    </inertial>
    <visual>
      <origin
        xyz="0 0 0"
        rpy="0 0 0" />
      <geometry>
        <mesh
          filename="package://oro_v4/meshes/neck.STL" />
      </geometry>
      <material
        name="">
        <color
          rgba="0.752941176470588 0.752941176470588 0.752941176470588 1" />
      </material>
    </visual>
    <collision>
      <origin
        xyz="0 0 0"
        rpy="0 0 0" />
      <geometry>
        <mesh
          filename="package://oro_v4/meshes/neck.STL" />
      </geometry>
    </collision>
  </link>
  <joint
    name="neck_joint"
    type="fixed">
    <origin
      xyz="-0.111522868965688 -0.223111765630108 0.978912848528942"
      rpy="0 0 -0.00709484089756157" />
    <parent
      link="base_link" />
    <child
      link="neck" />
    <axis
      xyz="0 0 0" />
  </joint>
  <link
    name="pan">
    <inertial>
      <origin
        xyz="0.138800226461537 0.037751689315611 0.048150180546507"
        rpy="0 0 0" />
      <mass
        value="0.044671122918534" />
      <inertia
        ixx="1.24175933971889E-05"
        ixy="2.93697424149573E-08"
        ixz="-5.12746900032759E-09"
        iyy="1.04155510489706E-05"
        iyz="1.82694302718639E-07"
        izz="7.78082243124476E-06" />
    </inertial>
    <visual>
      <origin
        xyz="0 0 0"
        rpy="0 0 0" />
      <geometry>
        <mesh
          filename="package://oro_v4/meshes/pan.STL" />
      </geometry>
      <material
        name="">
        <color
          rgba="0.752941176470588 0.752941176470588 0.752941176470588 1" />
      </material>
    </visual>
    <collision>
      <origin
        xyz="0 0 0"
        rpy="0 0 0" />
      <geometry>
        <mesh
          filename="package://oro_v4/meshes/pan.STL" />
      </geometry>
    </collision>
  </link>
  <joint
    name="pan_joint"
    type="continuous">
    <origin
      xyz="-0.0803690267279755 0.186890382040786 0.0492568279398251"
      rpy="0 0 -0.00757105682660417" />
    <parent
      link="neck" />
    <child
      link="pan" />
    <axis
      xyz="0 0 1" />
  </joint>
  <link
    name="tilt">
    <inertial>
      <origin
        xyz="-0.0391126868211261 -0.154233918312527 -0.102497825961896"
        rpy="0 0 0" />
      <mass
        value="0.190333592129278" />
      <inertia
        ixx="0.000184156831435667"
        ixy="2.86596668918669E-06"
        ixz="-1.08941936866102E-07"
        iyy="0.000483798101642879"
        iyz="-2.59296767496659E-06"
        izz="0.000309952349152964" />
    </inertial>
    <visual>
      <origin
        xyz="0 0 0"
        rpy="0 0 0" />
      <geometry>
        <mesh
          filename="package://oro_v4/meshes/tilt.STL" />
      </geometry>
      <material
        name="">
        <color
          rgba="0.894117647058823 0.913725490196078 0.929411764705882 1" />
      </material>
    </visual>
    <collision>
      <origin
        xyz="0 0 0"
        rpy="0 0 0" />
      <geometry>
        <mesh
          filename="package://oro_v4/meshes/tilt.STL" />
      </geometry>
    </collision>
  </link>
  <joint
    name="tilt_joint"
    type="continuous">
    <origin
      xyz="0.000250000000001249 0 0.0420800000000014"
      rpy="-3.12696731241166 0 -1.5707963267949" />
    <parent
      link="pan" />
    <child
      link="tilt" />
    <axis
      xyz="1 0 0" />
  </joint>
  <link
    name="depth_cam">
    <inertial>
      <origin
        xyz="-0.125165243976622 0.173957578005778 -0.139880750884658"
        rpy="0 0 0" />
      <mass
        value="0.153126621719676" />
      <inertia
        ixx="2.30119941588647E-05"
        ixy="7.57149862410181E-08"
        ixz="5.17446511699676E-06"
        iyy="0.000377926887835976"
        iyz="-2.9258298617135E-08"
        izz="0.000375771885888515" />
    </inertial>
    <visual>
      <origin
        xyz="0 0 0"
        rpy="0 0 0" />
      <geometry>
        <mesh
          filename="package://oro_v4/meshes/depth_cam.STL" />
      </geometry>
      <material
        name="">
        <color
          rgba="0.792156862745098 0.819607843137255 0.933333333333333 1" />
      </material>
    </visual>
    <collision>
      <origin
        xyz="0 0 0"
        rpy="0 0 0" />
      <geometry>
        <mesh
          filename="package://oro_v4/meshes/depth_cam.STL" />
      </geometry>
    </collision>
  </link>
  <joint
    name="depth_cam_joint"
    type="fixed">
    <origin
      xyz="0.0874623622012928 0 0"
      rpy="-1.57079632679489 0 0" />
    <parent
      link="tilt" />
    <child
      link="depth_cam" />
    <axis
      xyz="0 0 0" />
  </joint>
</robot>